Workbook

Sheet Start
D1: MSC Articleship Program | Work Simulation
D2: Accounting 1 · Excel: raw export to a register
A4: Tamhini Drivetech Private Limited · purchases of January–March 2027 · Wednesday 21 April 2027
A5: 1. Raw is Pallavi’s Excel copy of the Tally print. Leave it as it came: copy it, never clean it in place.
A6: 2. Register: paste a copy of the bills from row 6, headings in row 5. Take out every row that is not a bill, fix
A7: anything that would trip a formula, and bring each bill’s MSME status into column N from Vendors (exact match).
A8: 3. Tie: total each ledger from your register with SUMIFS, correct Varun’s two figures, and compare with the TB
A9: for the same three months.
A10: 4. Pivot: supplier by month from your register. What one point would you give Rehan?
A11: Enter your answers in the Work Simulation. Cells in pale yellow with a blue border are yours.
A14: Sheets: Raw · Vendors · TB · Varun (his checks and his tie) · Register · Tie · Pivot

Sheet Raw
B1: Tamhini Drivetech Private Limited
B2: B-47, MIDC Chakan Phase II, Pune 410501
B3: Purchase Register
B4: 1-Jan-2027 to 31-Mar-2027
A5: Date | B5: Particulars | C5: Vch No. | D5: Supplier Inv No. | E5: Supplier Inv Date | F5: GSTIN/UIN | G5: Purchase Ledger | H5: Taxable Value | I5: CGST | J5: SGST | K5: IGST | L5: Round Off | M5: Gross Total
A6: 46389 | B6: Kolak Polypack Private Limited | C6: 2251 | D6: KP/26-27/1253 | E6: 46386 | F6: 24WGHCK4121C1Z7 | G6: Purchases – packing materials | H6: 146000 | K6: 26280 | M6: 172280
B7: (Recd 2-1-2027 vide GRN-2027-01-0017)
A8: 46391 | B8: Moshi Corrugators | C8: 2271 | D8: MC/26-27/214 | E8: 46391 | F8: 27YNLPL0717M1Z1 | G8: Purchases – packing materials | H8: 76800 | I8: 1920 | J8: 1920 | M8: 80640
A9: 46394 | B9: Moshi Corrugators | C9: 2305 | D9: MC/26-27/217 | E9: 46394 | F9: 27YNLPL0717M1Z1 | G9: Purchases – packing materials | H9: 86400 | I9: 2160 | J9: 2160 | M9: 90720
B10: (Being 3,600 nos 3-ply boxes, GRN-2027-01-0086)
A11: 46394 | B11: Hebbal Tooling Solutions Private Limited | C11: 2308 | D11: HTS/26-27/0874 | E11: 46391 | F11: 29ZEMCH0865A1ZP | G11: Purchases – stores and consumables | H11: 312500 | K11: 56250 | M11: 368750
A12: 46395 | B12: Mundhwa Lubricants and Chemicals | C12: 2313 | D12: MLC/26-27/1196 | E12: 46395 | F12: 27WHQFM7542F1ZX | G12: Purchases – stores and consumables | H12: 394600 | I12: 35514 | J12: 35514 | M12: 465628
A13: 46400 | B13: Moshi Corrugators | C13: 2367 | D13: MC/26-27/222 | E13: 46400 | F13: 27YNLPL0717M1Z1 | G13: Purchases – packing materials | H13: 92160 | I13: 2304 | J13: 2304 | M13: 96768
A14: 46400 | B14: Alandi Paper Products | C14: 2370 | D14: APP/26-27/0149 | E14: 46399 | F14: 27ZDLPK9230K1ZG | G14: Purchases – packing materials | H14: 240000 | I14: 6000 | J14: 6000 | M14: 252000
A15: 46401 | B15: Hebbal Tooling Solutions Private Limited | C15: 2380 | D15: HTS/26-27/0879 | E15: 46398 | F15: 29ZEMCH0865A1ZP | G15: Purchases – stores and consumables | H15: 328000 | K15: 59040 | M15: 387040
A16: 46405 | B16: Moshi Corrugators | C16: 2421 | D16: MC/26-27/226 | E16: 46405 | F16: 27YNLPL0717M1Z1 | G16: Purchases – packing materials | H16: 86400 | I16: 2160 | J16: 2160 | M16: 90720
A17: 46406 | B17: Kolak Polypack Private Limited | C17: 2434 | D17: KP/26-27/1264 | E17: 46403 | F17: 24WGHCK4121C1Z7 | G17: Purchases – packing materials | H17: 136000 | K17: 24480 | M17: 160480
A18: 46406 | B18: Mundhwa Lubricants and Chemicals | C18: 2437 | D18: MLC/26-27/1238 | E18: 46406 | F18: 27WHQFM7542F1ZX | G18: Purchases – stores and consumables | H18: 348200 | I18: 31338 | J18: 31338 | M18: 410876
A19: 46408 | B19: Hebbal Tooling Solutions Private Limited | C19: 2454 | D19: HTS/26-27/0885 | E19: 46405 | F19: 29ZEMCH0865A1ZP | G19: Purchases – stores and consumables | H19: 297000 | K19: 53460 | M19: 350460
A20: 46409 | B20: Moshi Corrugators | C20: 2467 | D20: MC/26-27/229 | E20: 46409 | F20: 27YNLPL0717M1Z1 | G20: Purchases – packing materials | H20: 72000 | I20: 1800 | J20: 1800 | M20: 75600
A21: 46414 | B21: Mundhwa Lubricants and Chemicals | C21: 2521 | D21: MLC/26-27/1269 | E21: 46414 | F21: 27WHQFM7542F1ZX | G21: Purchases – stores and consumables | H21: 308200 | I21: 27738 | J21: 27738 | M21: 363676
A22: 46415 | B22: Moshi Corrugators | C22: 2529 | D22: MC/26-27/235 | E22: 46415 | F22: 27YNLPL0717M1Z1 | G22: Purchases – packing materials | H22: 85240 | I22: 2131 | J22: 2131 | M22: 89502
A23: 46415 | B23: Hebbal Tooling Solutions Private Limited | C23: 2532 | D23: HTS/26-27/0890 | E23: 46412 | F23: 29ZEMCH0865A1ZP | G23: Purchases – stores and consumables | H23: 346500 | K23: 62370 | M23: 408870
A24: 46416 | B24: Kolak Polypack Private Limited | C24: 2539 | D24: KP/26-27/1276 | E24: 46414 | F24: 24WGHCK4121C1Z7 | G24: Purchases – packing materials | H24: 104000 | K24: 18720 | M24: 122720
A25: 46420 | B25: Moshi Corrugators | C25: 2587 | D25: MC/26-27/240 | E25: 46420 | F25: 27YNLPL0717M1Z1 | G25: Purchases – packing materials | H25: 81600 | I25: 2040 | J25: 2040 | M25: 85680
A26: 46422 | B26: Hebbal Tooling Solutions Private Limited | C26: 2607 | D26: HTS/26-27/0896 | E26: 46419 | F26: 29ZEMCH0865A1ZP | G26: Purchases – stores and consumables | H26: 341000 | K26: 61380 | M26: 402380
B27: Carried Over | H27: 3882600 | I27: 115105 | J27: 115105 | K27: 361980 | M27: 4474790
B28: Purchase Register · Page 2
A29: Date | B29: Particulars | C29: Vch No. | D29: Supplier Inv No. | E29: Supplier Inv Date | F29: GSTIN/UIN | G29: Purchase Ledger | H29: Taxable Value | I29: CGST | J29: SGST | K29: IGST | L29: Round Off | M29: Gross Total
B30: Brought Forward | H30: 3882600 | I30: 115105 | J30: 115105 | K30: 361980 | M30: 4474790
A31: 46422 | B31: Hebbal Tooling Solutions Private Limited | C31: 2607 | D31: HTS/26-27/0896 | E31: 46419 | F31: 29ZEMCH0865A1ZP | G31: Purchases – stores and consumables | H31: 341000 | K31: 61380 | M31: 402380
A32: 46423 | B32: Kolak Polypack Private Limited | C32: 2615 | D32: KP/26-27/1288 | E32: 46421 | F32: 24WGHCK4121C1Z7 | G32: Purchases – packing materials | H32: 132000 | K32: 23760 | M32: 155760
A33: 46424 | B33: Moshi Corrugators | C33: 2628 | D33: MC/26-27/243 | E33: 46424 | F33: 27YNLPL0717M1Z1 | G33: Purchases – packing materials | H33: 90240 | I33: 2256 | J33: 2256 | M33: 94752
A34: 46427 | B34: Mundhwa Lubricants and Chemicals | C34: 2662 | D34: MLC/26-27/1311 | E34: 46427 | F34: 27WHQFM7542F1ZX | G34: Purchases – stores and consumables | H34: 460200 | I34: 41418 | J34: 41418 | M34: 543036
A35: 46428 | B35: Alandi Paper Products | C35: 2670 | D35: APP/26-27/0158 | E35: 46428 | F35: 27ZDLPK9230K1ZG | G35: Purchases – packing materials | H35: 250000 | I35: 6250 | J35: 6250 | M35: 262500
A36: 46429 | B36: Moshi Corrugators | C36: 2683 | D36: MC/26-27/247 | E36: 46429 | F36: 27YNLPL0717M1Z1 | G36: Purchases – packing materials | H36: 78720 | I36: 1968 | J36: 1968 | M36: 82656
A37: 46429 | B37: Hebbal Tooling Solutions Private Limited | C37: 2686 | D37: HTS/26-27/0902 | E37: 46426 | F37: 29ZEMCH0865A1ZP | G37: Purchases – stores and consumables | H37: 318500 | K37: 57330 | M37: 375830
A38: 46434 | B38: Moshi Corrugators | C38: 2737 | D38: MC/26-27/251 | E38: 46434 | F38: 27YNLPL0717M1Z1 | G38: Purchases – packing materials | H38: 88320 | I38: 2208 | J38: 2208 | M38: 92736
A39: 46436 | B39: Kolak Polypack Private Limited | C39: 2758 | D39: KP/26-27/1301 | E39: 46433 | F39: 24WGHCK4121C1Z7 | G39: Purchases – packing materials | H39: 138500.00 | K39: 24930.00 | M39: 163430.00
A40: 46436 | B40: Mundhwa Lubricants and Chemicals | C40: 2761 | D40: MLC/26-27/1347 | E40: 46436 | F40: 27WHQFM7542F1ZX | G40: Purchases – stores and consumables | H40: 378000 | I40: 34020 | J40: 34020 | M40: 446040
...

Sheet Vendors
A1: Tamhini Drivetech Private Limited · Vendor master (extract)
A2: Printed 20-04-2027
A3: Vendor | B3: GSTIN | C3: PAN | D3: State | E3: Vendor code | F3: Place | G3: MSME | H3: Credit days
A4: Ghanekar Alloy Steels Private Limited | B4: 27UMVCG6849R1ZY | C4: UMVCG6849R | D4: Maharashtra | E4: VEN-1001 | F4: Jalna | G4: – | H4: 60
A5: Kharun Steels Private Limited | B5: 22UFLCK0414F1Z9 | C5: UFLCK0414F | D5: Chhattisgarh | E5: VEN-1002 | F5: Raipur | G5: – | H5: 60
A6: Rankala Forgings Private Limited | B6: 27UJPCR7248B1Z1 | C6: UJPCR7248B | D6: Maharashtra | E6: VEN-1003 | F6: Kolhapur | G6: Small | H6: 45
A7: Bhadar Forge and Engineering Private Limited | B7: 24YLTCB8047E1Z6 | C7: YLTCB8047E | D7: Gujarat | E7: VEN-1004 | F7: Rajkot | G7: – | H7: 60
A8: Vishwamitri Bearings Private Limited | B8: 24UQQCV0863H1ZL | C8: UQQCV0863H | D8: Gujarat | E8: VEN-1005 | F8: Vadodara | G8: – | H8: 60
A9: Palar Seals and Gaskets Private Limited | B9: 33VMJCP6724Z1Z1 | C9: VMJCP6724Z | D9: Tamil Nadu | E9: VEN-1006 | F9: Chennai | G9: – | H9: 60
A10: Sohna Friction Products Private Limited | B10: 06ZDICS4933L1Z4 | C10: ZDICS4933L | D10: Haryana | E10: VEN-1007 | F10: Gurugram | G10: – | H10: 60
A11: Phillaur Fasteners Private Limited | B11: 03UBZCP4197S1ZJ | C11: UBZCP4197S | D11: Punjab | E11: VEN-1008 | F11: Ludhiana | G11: Small | H11: 45
A12: Hebbal Tooling Solutions Private Limited | B12: 29ZEMCH0865A1ZP | C12: ZEMCH0865A | D12: Karnataka | E12: VEN-1009 | F12: Bengaluru | G12: – | H12: 45
A13: Mundhwa Lubricants and Chemicals | B13: 27WHQFM7542F1ZX | C13: WHQFM7542F | D13: Maharashtra | E13: VEN-1010 | F13: Pune | G13: – | H13: 30
A14: Moshi Corrugators (Prop. Ramesh Landge) | B14: 27YNLPL0717M1Z1 | C14: YNLPL0717M | D14: Maharashtra | E14: VEN-1011 | F14: Pune | G14: Micro | H14: 30
A15: Alandi Paper Products (Prop. Kiran Kurhade) | B15: 27ZDLPK9230K1ZG | C15: ZDLPK9230K | D15: Maharashtra | E15: VEN-1012 | F15: Alandi | G15: Micro | H15: 30
... A18: Sakhare Surface Treatment | B18: 27ZJGPS6000S1ZY | C18: ZJGPS6000S | D18: Maharashtra | E18: VEN-1015 | F18: Chakan | G18: Micro | H18: 30

Sheet TB
A1: Tamhini Drivetech Private Limited
A2: Trial Balance · 1-Jan-2027 to 31-Mar-2027 · extract, typed from the Tally print
A4: Particulars | B4: Opening Balance (Dr) | C4: Transactions: Debit | D4: Transactions: Credit | E4: Closing Balance (Dr)
A5: Purchases – raw materials | B5: 409005000 | C5: 139995000 | E5: 549000000
A6: Purchases – bought-out parts | B6: 24734000 | C6: 8466000 | E6: 33200000
A7: Purchases – traded goods | B7: 109366000 | C7: 37434000 | E7: 146800000
A8: Purchases – stores and consumables | B8: 20711000 | C8: 7089000 | E8: 27800000
A9: Purchases – packing materials | B9: 9983000 | C9: 3417000 | E9: 13400000
A10: Purchase Accounts | B10: 573799000 | C10: 196401000 | E10: 770200000

Sheet Varun
B1: Tamhini Drivetech Private Limited
B2: B-47, MIDC Chakan Phase II, Pune 410501
B3: Purchase Register
B4: 1-Jan-2027 to 31-Mar-2027 | Q4: Ledger | R4: Register (SUMIFS) | S4: TB | T4: Difference
A5: Date | B5: Particulars | C5: Vch No. | D5: Supplier Inv No. | E5: Supplier Inv Date | F5: GSTIN/UIN | G5: Purchase Ledger | H5: Taxable Value | I5: CGST | J5: SGST | K5: IGST | L5: Round Off | M5: Gross Total | N5: MSME (lookup) | O5: Same party + amount | Q5: Purchases – packing materials | R5: =SUMIFS($H$6:$H$71, $G$6:$G$71, Q5) -> 3278500 | S5: 13400000 | T5: =R5-S5 -> -10121500
A6: 46389 | B6: Kolak Polypack Private Limited | C6: 2251 | D6: KP/26-27/1253 | E6: 46386 | F6: 24WGHCK4121C1Z7 | G6: Purchases – packing materials | H6: 146000 | K6: 26280 | M6: 172280 | N6: =VLOOKUP(F6, Vendors!$B$4:$H$18, 6, FALSE) -> Small | O6: =IF(ISNUMBER(H6), COUNTIFS($B$6:$B$71, B6, $H$6:$H$71, H6), 0) -> 1 | Q6: Purchases – stores and consumables | R6: =SUMIFS($H$6:$H$71, $G$6:$G$71, Q6) -> 7430000 | S6: 27800000 | T6: =R6-S6 -> -20370000
B7: (Recd 2-1-2027 vide GRN-2027-01-0017) | N7: =VLOOKUP(F7, Vendors!$B$4:$H$18, 6, FALSE) -> #N/A | O7: =IF(ISNUMBER(H7), COUNTIFS($B$6:$B$71, B7, $H$6:$H$71, H7), 0) -> 0 | Q7: Total | R7: =R5+R6 -> 10708500 | S7: =S5+S6 -> 41200000 | T7: =T5+T6 -> -30491500
A8: 46391 | B8: Moshi Corrugators | C8: 2271 | D8: MC/26-27/214 | E8: 46391 | F8: 27YNLPL0717M1Z1 | G8: Purchases – packing materials | H8: 76800 | I8: 1920 | J8: 1920 | M8: 80640 | N8: =VLOOKUP(F8, Vendors!$B$4:$H$18, 6, FALSE) -> Micro | O8: =IF(ISNUMBER(H8), COUNTIFS($B$6:$B$71, B8, $H$6:$H$71, H8), 0) -> 1
A9: 46394 | B9: Moshi Corrugators | C9: 2305 | D9: MC/26-27/217 | E9: 46394 | F9: 27YNLPL0717M1Z1 | G9: Purchases – packing materials | H9: 86400 | I9: 2160 | J9: 2160 | M9: 90720 | N9: =VLOOKUP(F9, Vendors!$B$4:$H$18, 6, FALSE) -> Micro | O9: =IF(ISNUMBER(H9), COUNTIFS($B$6:$B$71, B9, $H$6:$H$71, H9), 0) -> 2 | Q9: Doesn’t tie. Out by crores on both??
B10: (Being 3,600 nos 3-ply boxes, GRN-2027-01-0086) | N10: =VLOOKUP(F10, Vendors!$B$4:$H$18, 6, FALSE) -> #N/A | O10: =IF(ISNUMBER(H10), COUNTIFS($B$6:$B$71, B10, $H$6:$H$71, H10), 0) -> 0 | Q10: Will look again tomorrow. V
A11: 46394 | B11: Hebbal Tooling Solutions Private Limited | C11: 2308 | D11: HTS/26-27/0874 | E11: 46391 | F11: 29ZEMCH0865A1ZP | G11: Purchases – stores and consumables | H11: 312500 | K11: 56250 | M11: 368750 | N11: =VLOOKUP(F11, Vendors!$B$4:$H$18, 6, FALSE) -> – | O11: =IF(ISNUMBER(H11), COUNTIFS($B$6:$B$71, B11, $H$6:$H$71, H11), 0) -> 1
A12: 46395 | B12: Mundhwa Lubricants and Chemicals | C12: 2313 | D12: MLC/26-27/1196 | E12: 46395 | F12: 27WHQFM7542F1ZX | G12: Purchases – stores and consumables | H12: 394600 | I12: 35514 | J12: 35514 | M12: 465628 | N12: =VLOOKUP(F12, Vendors!$B$4:$H$18, 6, FALSE) -> – | O12: =IF(ISNUMBER(H12), COUNTIFS($B$6:$B$71, B12, $H$6:$H$71, H12), 0) -> 1
A13: 46400 | B13: Moshi Corrugators | C13: 2367 | D13: MC/26-27/222 | E13: 46400 | F13: 27YNLPL0717M1Z1 | G13: Purchases – packing materials | H13: 92160 | I13: 2304 | J13: 2304 | M13: 96768 | N13: =VLOOKUP(F13, Vendors!$B$4:$H$18, 6, FALSE) -> Micro | O13: =IF(ISNUMBER(H13), COUNTIFS($B$6:$B$71, B13, $H$6:$H$71, H13), 0) -> 1
A14: 46400 | B14: Alandi Paper Products | C14: 2370 | D14: APP/26-27/0149 | E14: 46399 | F14: 27ZDLPK9230K1ZG | G14: Purchases – packing materials | H14: 240000 | I14: 6000 | J14: 6000 | M14: 252000 | N14: =VLOOKUP(F14, Vendors!$B$4:$H$18, 6, FALSE) -> Micro | O14: =IF(ISNUMBER(H14), COUNTIFS($B$6:$B$71, B14, $H$6:$H$71, H14), 0) -> 1
A15: 46401 | B15: Hebbal Tooling Solutions Private Limited | C15: 2380 | D15: HTS/26-27/0879 | E15: 46398 | F15: 29ZEMCH0865A1ZP | G15: Purchases – stores and consumables | H15: 328000 | K15: 59040 | M15: 387040 | N15: =VLOOKUP(F15, Vendors!$B$4:$H$18, 6, FALSE) -> – | O15: =IF(ISNUMBER(H15), COUNTIFS($B$6:$B$71, B15, $H$6:$H$71, H15), 0) -> 1
A16: 46405 | B16: Moshi Corrugators | C16: 2421 | D16: MC/26-27/226 | E16: 46405 | F16: 27YNLPL0717M1Z1 | G16: Purchases – packing materials | H16: 86400 | I16: 2160 | J16: 2160 | M16: 90720 | N16: =VLOOKUP(F16, Vendors!$B$4:$H$18, 6, FALSE) -> Micro | O16: =IF(ISNUMBER(H16), COUNTIFS($B$6:$B$71, B16, $H$6:$H$71, H16), 0) -> 2
A17: 46406 | B17: Kolak Polypack Private Limited | C17: 2434 | D17: KP/26-27/1264 | E17: 46403 | F17: 24WGHCK4121C1Z7 | G17: Purchases – packing materials | H17: 136000 | K17: 24480 | M17: 160480 | N17: =VLOOKUP(F17, Vendors!$B$4:$H$18, 6, FALSE) -> Small | O17: =IF(ISNUMBER(H17), COUNTIFS($B$6:$B$71, B17, $H$6:$H$71, H17), 0) -> 1
A18: 46406 | B18: Mundhwa Lubricants and Chemicals | C18: 2437 | D18: MLC/26-27/1238 | E18: 46406 | F18: 27WHQFM7542F1ZX | G18: Purchases – stores and consumables | H18: 348200 | I18: 31338 | J18: 31338 | M18: 410876 | N18: =VLOOKUP(F18, Vendors!$B$4:$H$18, 6, FALSE) -> #N/A | O18: =IF(ISNUMBER(H18), COUNTIFS($B$6:$B$71, B18, $H$6:$H$71, H18), 0) -> 1
A19: 46408 | B19: Hebbal Tooling Solutions Private Limited | C19: 2454 | D19: HTS/26-27/0885 | E19: 46405 | F19: 29ZEMCH0865A1ZP | G19: Purchases – stores and consumables | H19: 297000 | K19: 53460 | M19: 350460 | N19: =VLOOKUP(F19, Vendors!$B$4:$H$18, 6, FALSE) -> – | O19: =IF(ISNUMBER(H19), COUNTIFS($B$6:$B$71, B19, $H$6:$H$71, H19), 0) -> 1
A20: 46409 | B20: Moshi Corrugators | C20: 2467 | D20: MC/26-27/229 | E20: 46409 | F20: 27YNLPL0717M1Z1 | G20: Purchases – packing materials | H20: 72000 | I20: 1800 | J20: 1800 | M20: 75600 | N20: =VLOOKUP(F20, Vendors!$B$4:$H$18, 6, FALSE) -> Micro | O20: =IF(ISNUMBER(H20), COUNTIFS($B$6:$B$71, B20, $H$6:$H$71, H20), 0) -> 1
A21: 46414 | B21: Mundhwa Lubricants and Chemicals | C21: 2521 | D21: MLC/26-27/1269 | E21: 46414 | F21: 27WHQFM7542F1ZX | G21: Purchases – stores and consumables | H21: 308200 | I21: 27738 | J21: 27738 | M21: 363676 | N21: =VLOOKUP(F21, Vendors!$B$4:$H$18, 6, FALSE) -> – | O21: =IF(ISNUMBER(H21), COUNTIFS($B$6:$B$71, B21, $H$6:$H$71, H21), 0) -> 1
A22: 46415 | B22: Moshi Corrugators | C22: 2529 | D22: MC/26-27/235 | E22: 46415 | F22: 27YNLPL0717M1Z1 | G22: Purchases – packing materials | H22: 85240 | I22: 2131 | J22: 2131 | M22: 89502 | N22: =VLOOKUP(F22, Vendors!$B$4:$H$18, 6, FALSE) -> Micro | O22: =IF(ISNUMBER(H22), COUNTIFS($B$6:$B$71, B22, $H$6:$H$71, H22), 0) -> 1
A23: 46415 | B23: Hebbal Tooling Solutions Private Limited | C23: 2532 | D23: HTS/26-27/0890 | E23: 46412 | F23: 29ZEMCH0865A1ZP | G23: Purchases – stores and consumables | H23: 346500 | K23: 62370 | M23: 408870 | N23: =VLOOKUP(F23, Vendors!$B$4:$H$18, 6, FALSE) -> – | O23: =IF(ISNUMBER(H23), COUNTIFS($B$6:$B$71, B23, $H$6:$H$71, H23), 0) -> 1
A24: 46416 | B24: Kolak Polypack Private Limited | C24: 2539 | D24: KP/26-27/1276 | E24: 46414 | F24: 24WGHCK4121C1Z7 | G24: Purchases – packing materials | H24: 104000 | K24: 18720 | M24: 122720 | N24: =VLOOKUP(F24, Vendors!$B$4:$H$18, 6, FALSE) -> Small | O24: =IF(ISNUMBER(H24), COUNTIFS($B$6:$B$71, B24, $H$6:$H$71, H24), 0) -> 1
A25: 46420 | B25: Moshi Corrugators | C25: 2587 | D25: MC/26-27/240 | E25: 46420 | F25: 27YNLPL0717M1Z1 | G25: Purchases – packing materials | H25: 81600 | I25: 2040 | J25: 2040 | M25: 85680 | N25: =VLOOKUP(F25, Vendors!$B$4:$H$18, 6, FALSE) -> Micro | O25: =IF(ISNUMBER(H25), COUNTIFS($B$6:$B$71, B25, $H$6:$H$71, H25), 0) -> 1
A26: 46422 | B26: Hebbal Tooling Solutions Private Limited | C26: 2607 | D26: HTS/26-27/0896 | E26: 46419 | F26: 29ZEMCH0865A1ZP | G26: Purchases – stores and consumables | H26: 341000 | K26: 61380 | M26: 402380 | N26: =VLOOKUP(F26, Vendors!$B$4:$H$18, 6, FALSE) -> – | O26: =IF(ISNUMBER(H26), COUNTIFS($B$6:$B$71, B26, $H$6:$H$71, H26), 0) -> 2
B27: Carried Over | H27: 3882600 | I27: 115105 | J27: 115105 | K27: 361980 | M27: 4474790 | N27: =VLOOKUP(F27, Vendors!$B$4:$H$18, 6, FALSE) -> #N/A | O27: =IF(ISNUMBER(H27), COUNTIFS($B$6:$B$71, B27, $H$6:$H$71, H27), 0) -> 1
B28: Purchase Register · Page 2 | N28: =VLOOKUP(F28, Vendors!$B$4:$H$18, 6, FALSE) -> #N/A | O28: =IF(ISNUMBER(H28), COUNTIFS($B$6:$B$71, B28, $H$6:$H$71, H28), 0) -> 0
A29: Date | B29: Particulars | C29: Vch No. | D29: Supplier Inv No. | E29: Supplier Inv Date | F29: GSTIN/UIN | G29: Purchase Ledger | H29: Taxable Value | I29: CGST | J29: SGST | K29: IGST | L29: Round Off | M29: Gross Total | N29: =VLOOKUP(F29, Vendors!$B$4:$H$18, 6, FALSE) -> #N/A | O29: =IF(ISNUMBER(H29), COUNTIFS($B$6:$B$71, B29, $H$6:$H$71, H29), 0) -> 0
B30: Brought Forward | H30: 3882600 | I30: 115105 | J30: 115105 | K30: 361980 | M30: 4474790 | N30: =VLOOKUP(F30, Vendors!$B$4:$H$18, 6, FALSE) -> #N/A | O30: =IF(ISNUMBER(H30), COUNTIFS($B$6:$B$71, B30, $H$6:$H$71, H30), 0) -> 1
A31: 46422 | B31: Hebbal Tooling Solutions Private Limited | C31: 2607 | D31: HTS/26-27/0896 | E31: 46419 | F31: 29ZEMCH0865A1ZP | G31: Purchases – stores and consumables | H31: 341000 | K31: 61380 | M31: 402380 | N31: =VLOOKUP(F31, Vendors!$B$4:$H$18, 6, FALSE) -> – | O31: =IF(ISNUMBER(H31), COUNTIFS($B$6:$B$71, B31, $H$6:$H$71, H31), 0) -> 2
A32: 46423 | B32: Kolak Polypack Private Limited | C32: 2615 | D32: KP/26-27/1288 | E32: 46421 | F32: 24WGHCK4121C1Z7 | G32: Purchases – packing materials | H32: 132000 | K32: 23760 | M32: 155760 | N32: =VLOOKUP(F32, Vendors!$B$4:$H$18, 6, FALSE) -> Small | O32: =IF(ISNUMBER(H32), COUNTIFS($B$6:$B$71, B32, $H$6:$H$71, H32), 0) -> 1
A33: 46424 | B33: Moshi Corrugators | C33: 2628 | D33: MC/26-27/243 | E33: 46424 | F33: 27YNLPL0717M1Z1 | G33: Purchases – packing materials | H33: 90240 | I33: 2256 | J33: 2256 | M33: 94752 | N33: =VLOOKUP(F33, Vendors!$B$4:$H$18, 6, FALSE) -> Micro | O33: =IF(ISNUMBER(H33), COUNTIFS($B$6:$B$71, B33, $H$6:$H$71, H33), 0) -> 1
A34: 46427 | B34: Mundhwa Lubricants and Chemicals | C34: 2662 | D34: MLC/26-27/1311 | E34: 46427 | F34: 27WHQFM7542F1ZX | G34: Purchases – stores and consumables | H34: 460200 | I34: 41418 | J34: 41418 | M34: 543036 | N34: =VLOOKUP(F34, Vendors!$B$4:$H$18, 6, FALSE) -> – | O34: =IF(ISNUMBER(H34), COUNTIFS($B$6:$B$71, B34, $H$6:$H$71, H34), 0) -> 1
A35: 46428 | B35: Alandi Paper Products | C35: 2670 | D35: APP/26-27/0158 | E35: 46428 | F35: 27ZDLPK9230K1ZG | G35: Purchases – packing materials | H35: 250000 | I35: 6250 | J35: 6250 | M35: 262500 | N35: =VLOOKUP(F35, Vendors!$B$4:$H$18, 6, FALSE) -> Micro | O35: =IF(ISNUMBER(H35), COUNTIFS($B$6:$B$71, B35, $H$6:$H$71, H35), 0) -> 1
A36: 46429 | B36: Moshi Corrugators | C36: 2683 | D36: MC/26-27/247 | E36: 46429 | F36: 27YNLPL0717M1Z1 | G36: Purchases – packing materials | H36: 78720 | I36: 1968 | J36: 1968 | M36: 82656 | N36: =VLOOKUP(F36, Vendors!$B$4:$H$18, 6, FALSE) -> Micro | O36: =IF(ISNUMBER(H36), COUNTIFS($B$6:$B$71, B36, $H$6:$H$71, H36), 0) -> 1
A37: 46429 | B37: Hebbal Tooling Solutions Private Limited | C37: 2686 | D37: HTS/26-27/0902 | E37: 46426 | F37: 29ZEMCH0865A1ZP | G37: Purchases – stores and consumables | H37: 318500 | K37: 57330 | M37: 375830 | N37: =VLOOKUP(F37, Vendors!$B$4:$H$18, 6, FALSE) -> – | O37: =IF(ISNUMBER(H37), COUNTIFS($B$6:$B$71, B37, $H$6:$H$71, H37), 0) -> 1
A38: 46434 | B38: Moshi Corrugators | C38: 2737 | D38: MC/26-27/251 | E38: 46434 | F38: 27YNLPL0717M1Z1 | G38: Purchases – packing materials | H38: 88320 | I38: 2208 | J38: 2208 | M38: 92736 | N38: =VLOOKUP(F38, Vendors!$B$4:$H$18, 6, FALSE) -> Micro | O38: =IF(ISNUMBER(H38), COUNTIFS($B$6:$B$71, B38, $H$6:$H$71, H38), 0) -> 1
A39: 46436 | B39: Kolak Polypack Private Limited | C39: 2758 | D39: KP/26-27/1301 | E39: 46433 | F39: 24WGHCK4121C1Z7 | G39: Purchases – packing materials | H39: 138500.00 | K39: 24930.00 | M39: 163430.00 | N39: =VLOOKUP(F39, Vendors!$B$4:$H$18, 6, FALSE) -> Small | O39: =IF(ISNUMBER(H39), COUNTIFS($B$6:$B$71, B39, $H$6:$H$71, H39), 0) -> 0
A40: 46436 | B40: Mundhwa Lubricants and Chemicals | C40: 2761 | D40: MLC/26-27/1347 | E40: 46436 | F40: 27WHQFM7542F1ZX | G40: Purchases – stores and consumables | H40: 378000 | I40: 34020 | J40: 34020 | M40: 446040 | N40: =VLOOKUP(F40, Vendors!$B$4:$H$18, 6, FALSE) -> – | O40: =IF(ISNUMBER(H40), COUNTIFS($B$6:$B$71, B40, $H$6:$H$71, H40), 0) -> 1
...

Sheet Register
D1: Your register
D2: Bills only: one row per bill, January–March 2027, from row 6. Headings stay in row 5.
A3: Paste a copy from Raw, then clean it here: rows 6 to the last bill, no gaps, nothing that is not a bill.
A4: Column N: each bill’s MSME status from Vendors, with an exact-match lookup on the GSTIN in column F.
A5: Date | B5: Particulars | C5: Vch No. | D5: Supplier Inv No. | E5: Supplier Inv Date | F5: GSTIN/UIN | G5: Purchase Ledger | H5: Taxable Value | I5: CGST | J5: SGST | K5: IGST | L5: Round Off | M5: Gross Total | N5: MSME status

Sheet Tie
D1: Tie the register to the TB
D2: January–March 2027 · whole rupees
B4: Line | C4: Purchases – packing materials | D4: Purchases – stores and consumables | F4: How to fill it
B5: Varun’s SUMIFS on the raw sheet | C5: =SUMIFS(Varun!$H$6:$H$71, Varun!$G$6:$G$71, C$4) -> 3278500 | D5: =SUMIFS(Varun!$H$6:$H$71, Varun!$G$6:$G$71, D$4) -> 7430000 | F5: Corrections: plus adds back, minus takes out.
B6: Correction 1 (which row, and why) | F6: Your register: SUMIFS on the Register sheet.
B7: Correction 2 (which row, and why) | F7: TB: the column that covers January–March.
B8: Your register, January–March | F8: Difference: register less TB.
B9: TB, the same three months | F9: Enter the figures in the Work Simulation.
B10: Difference

Sheet Pivot
D1: Supplier by month
D2: A PivotTable from your register
A4: Build it here
A5: Source: your register, Register!A5:N55, headings included.
A6: Rows: Purchase Ledger, then Particulars. Columns: Date, grouped by month.
A7: Values: Sum of Taxable Value (a Count means a blank cell or a text amount is still in the source).
A8: Read each supplier across, January to March.
A9: What one point would you give Rehan? Write it in the Work Simulation.
